Workbook

Sheet PFM
C2: 公牛集团 PFM 经营驱动模型
C3: r4b · Post-demo revision 2026-09-07 · 2026H1 actuals + Jul2026-Dec2028 monthly forecasts.
G7: 2026E | H7: 2027E | I7: 2028E
C9: Revenue 收入 | G9: =Annual!G9 -> 16533.137 | H9: =Annual!H9 -> 17127.709 | I9: =Annual!I9 -> 17753.04
C10: Gross profit 毛利 | G10: =Annual!G11 -> 6669.0324 | H10: =Annual!H11 -> 7085.4886 | I10: =Annual!I11 -> 7174.0035
C11: Gross margin 毛利率 | G11: =Annual!G64 -> 0.40337368 | H11: =Annual!H64 -> 0.41368572 | I11: =Annual!I64 -> 0.40410001
C12: Net income 净利润 | G12: =Annual!G23 -> 3929.6811 | H12: =Annual!H23 -> 4115.1327 | I12: =Annual!I23 -> 4132.7821
C14: Operating cash flow 经营现金流 | G14: =Annual!G56 -> 3559.4628 | H14: =Annual!H56 -> 4061.6758 | I14: =Annual!I56 -> 4091.7066
C15: Closing cash 期末现金 | G15: =Annual!G61 -> 2313.6962 | H15: =Annual!H61 -> 2495.3179 | I15: =Annual!I61 -> 2533.478
C16: Balance sheet difference 资产负债差额 | G16: =Annual!G53 -> 0 | H16: =Annual!H53 -> 0 | I16: =Annual!I53 -> 0
C19: Minimum monthly cash 月度现金低点 | G19: =MIN(Monthly_BS!J10:O10) -> 1139.6766 | H19: =MIN(Monthly_BS!P10:AA10) -> 947.77897 | I19: =MIN(Monthly_BS!AB10:AM10) -> 981.08402
C20: Maximum monthly BS difference 月度平衡差额 | G20: =MAX(MAX(Checks!J9:O9),-MIN(Checks!J9:O9)) -> 0 | H20: =MAX(MAX(Checks!P9:AA9),-MIN(Checks!P9:AA9)) -> 0 | I20: =MAX(MAX(Checks!AB9:AM9),-MIN(Checks!AB9:AM9)) -> 0
C21: Invalid input count 输入错误数 | G21: =SUM(Checks!J27:O27)+SUM(Liquidity!J57:O57) -> 0 | H21: =SUM(Checks!P27:AA27)+SUM(Liquidity!P57:AA57) -> 0 | I21: =SUM(Checks!AB27:AM27)+SUM(Liquidity!AB57:AM57) -> 0
C22: Investment redemptions 投资赎回 | G22: =SUM(Liquidity!J34:O34) -> 0 | H22: =SUM(Liquidity!P34:AA34) -> 0 | I22: =SUM(Liquidity!AB34:AM34) -> 0
C23: Peak standby RCF 备用融资峰值 | G23: =MAX(Liquidity!J48:O48) -> 0 | H23: =MAX(Liquidity!P48:AA48) -> 0 | I23: =MAX(Liquidity!AB48:AM48) -> 0
C24: Monthly operating build
C25: Product sales / net ASP; production requirement; physical FG; material consumption and purchases; weighted-average FG cost; source stock-category rolls.
C28: Payroll and Opex
C29: Four functional headcount rolls; remuneration/person; disclosed selling/admin/R&D expense lines. Production payroll and manufacturing D&A flow through inventory.
C32: Treasury and accounting
C33: Separate pledged/credit/long loans and leases; requested/effective funding; taxes, DTA/DTL, reserves/NCI; direct and indirect monthly CFO.
C36: Source and scope boundary
C37: H1 2026 PL/BS/CFS are reported actuals. Forecast starts July from the actual balance sheet. Investment windows and standby RCF remain planning assumptions.
C40: What remains unbuilt
C41: Open: product-level maturity and redemption terms, committed facility contracts, monthly management accounts, HKFRS and filing sufficiency work.
C47: → Revenue
C48: → Production
C49: → Payroll | L49: Year | M49: Revenue | N49: Net income
C50: → ExpenseDetail | L50: 2023A | M50: =Annual!D9 -> 15694.756 | N50: =Annual!D23 -> 3864.3265
C51: → Inventory | L51: 2024A | M51: =Annual!E9 -> 16830.541 | N51: =Annual!E23 -> 4269.1759
C52: → Assets | L52: 2025A | M52: =Annual!F9 -> 16026.313 | N52: =Annual!F23 -> 4076.302
C53: → Funding | L53: 2026E | M53: =Annual!G9 -> 16533.137 | N53: =Annual!G23 -> 3929.6811
C54: → Checks | L54: 2027E | M54: =Annual!H9 -> 17127.709 | N54: =Annual!H23 -> 4115.1327
C55: → ReadMe | L55: 2028E | M55: =Annual!I9 -> 17753.04 | N55: =Annual!I23 -> 4132.7821
L58: Month | M58: Closing cash | N58: CFO
L59: 2026-01 | M59: =Monthly_CF!D51 -> 0 | N59: =Monthly_CF!D24 -> 0
L60: 2026-02 | M60: =Monthly_CF!E51 -> 0 | N60: =Monthly_CF!E24 -> 0
L61: 2026-03 | M61: =Monthly_CF!F51 -> 0 | N61: =Monthly_CF!F24 -> 0
L62: 2026-04 | M62: =Monthly_CF!G51 -> 0 | N62: =Monthly_CF!G24 -> 0
L63: 2026-05 | M63: =Monthly_CF!H51 -> 0 | N63: =Monthly_CF!H24 -> 0
...

Sheet Annual
C2: 公牛集团 Annual
C3: RMB million except units, people, RMB/person and explicit rates. Monthly forecasts, not monthly actuals.
D7: 2023A | E7: 2024A | F7: 2025A | G7: 2026E | H7: 2027E | I7: 2028E
C9: Revenue | D9: =SourceHistory!D9 -> 15694.756 | E9: =SourceHistory!E9 -> 16830.541 | F9: =SourceHistory!F9 -> 16026.313 | G9: =H1Actual!D9+(SUM(Monthly_PL!J10:O10)) -> 16533.137 | H9: =SUM(Monthly_PL!P10:AA10) -> 17127.709 | I9: =SUM(Monthly_PL!AB10:AM10) -> 17753.04
C10: COGS | D10: =SourceHistory!D10 -> 8914.1845 | E10: =SourceHistory!E10 -> 9551.8091 | F10: =SourceHistory!F10 -> 9113.1866 | G10: =H1Actual!D10+(SUM(Monthly_PL!J14:O14)) -> 9864.1046 | H10: =SUM(Monthly_PL!P14:AA14) -> 10042.22 | I10: =SUM(Monthly_PL!AB14:AM14) -> 10579.036
C11: Gross profit | D11: =D9-D10 -> 6780.5711 | E11: =E9-E10 -> 7278.732 | F11: =F9-F10 -> 6913.1259 | G11: =H1Actual!D11+(SUM(Monthly_PL!J15:O15)) -> 6669.0324 | H11: =SUM(Monthly_PL!P15:AA15) -> 7085.4886 | I11: =SUM(Monthly_PL!AB15:AM15) -> 7174.0035
C13: Selling expenses | D13: =SourceHistory!D11 -> 1070.4382 | E13: =SourceHistory!E11 -> 1369.4149 | F13: =SourceHistory!F11 -> 1183.4786 | G13: =H1Actual!D13+(SUM(Monthly_PL!J18:O18)) -> 1187.5263 | H13: =SUM(Monthly_PL!P18:AA18) -> 1250.9533 | I13: =SUM(Monthly_PL!AB18:AM18) -> 1287.8886
C14: Administration | D14: =SourceHistory!D12 -> 626.19855 | E14: =SourceHistory!E12 -> 732.04584 | F14: =SourceHistory!F12 -> 712.37518 | G14: =H1Actual!D14+(SUM(Monthly_PL!J19:O19)) -> 667.40903 | H14: =SUM(Monthly_PL!P19:AA19) -> 744.38039 | I14: =SUM(Monthly_PL!AB19:AM19) -> 766.80012
C15: R&D | D15: =SourceHistory!D13 -> 673.42739 | E15: =SourceHistory!E13 -> 745.51022 | F15: =SourceHistory!F13 -> 643.96378 | G15: =H1Actual!D15+(SUM(Monthly_PL!J20:O20)) -> 615.89423 | H15: =SUM(Monthly_PL!P20:AA20) -> 682.96445 | I15: =SUM(Monthly_PL!AB20:AM20) -> 704.69346
C16: Surcharges | D16: =SourceHistory!D14 -> 132.79617 | E16: =SourceHistory!E14 -> 133.17808 | F16: =SourceHistory!F14 -> 153.5287 | G16: =H1Actual!D16+(SUM(Monthly_PL!J21:O21)) -> 154.45554 | H16: =SUM(Monthly_PL!P21:AA21) -> 164.07985 | I16: =SUM(Monthly_PL!AB21:AM21) -> 170.07039
C17: Credit and asset impairment | D17: not mapped separately | E17: not mapped separately | F17: not mapped separately | G17: =H1Actual!D17+(SUM(Monthly_PL!J22:O22)+SUM(Monthly_PL!J23:O23)) -> 14.648504 | H17: =SUM(Monthly_PL!P22:AA22)+SUM(Monthly_PL!P23:AA23) -> 0.9843459 | I17: =SUM(Monthly_PL!AB22:AM22)+SUM(Monthly_PL!AB23:AM23) -> 1.0359089
C18: Other pretax/investment income | D18: =SourceHistory!D17 -> 150.1138 | E18: =SourceHistory!E17 -> 663.70528 | F18: =SourceHistory!F17 -> 588.91613 | G18: =H1Actual!D18+(SUM(Monthly_PL!J24:O24)+SUM(Monthly_PL!J25:O25)+SUM(Monthly_PL!J26:O26)) -> 652.48068 | H18: =SUM(Monthly_PL!P24:AA24)+SUM(Monthly_PL!P25:AA25)+SUM(Monthly_PL!P26:AA26) -> 658.17361 | I18: =SUM(Monthly_PL!AB24:AM24)+SUM(Monthly_PL!AB25:AM25)+SUM(Monthly_PL!AB26:AM26) -> 665.89385
C19: Net finance expense | D19: =SourceHistory!D15 -> -108.51035 | E19: =SourceHistory!E15 -> -118.16772 | F19: =SourceHistory!F15 -> -96.686209 | G19: =H1Actual!D19+(SUM(Monthly_PL!J28:O28)+-SUM(Monthly_PL!J27:O27)) -> -67.192569 | H19: =SUM(Monthly_PL!P28:AA28)+-SUM(Monthly_PL!P27:AA27) -> -91.620505 | I19: =SUM(Monthly_PL!AB28:AM28)+-SUM(Monthly_PL!AB27:AM27) -> -103.92139
C21: Profit before tax | D21: =SourceHistory!D18 -> 4536.335 | E21: =SourceHistory!E18 -> 5080.4559 | F21: =SourceHistory!F18 -> 4905.382 | G21: =H1Actual!D21+(SUM(Monthly_PL!J29:O29)) -> 4748.7721 | H21: =SUM(Monthly_PL!P29:AA29) -> 4991.9203 | I21: =SUM(Monthly_PL!AB29:AM29) -> 5013.3302
C22: Income tax | D22: =SourceHistory!D19 -> 672.00846 | E22: =SourceHistory!E19 -> 811.28001 | F22: =SourceHistory!F19 -> 829.07993 | G22: =H1Actual!D22+(SUM(Monthly_PL!J30:O30)) -> 819.09097 | H22: =SUM(Monthly_PL!P30:AA30) -> 876.78767 | I22: =SUM(Monthly_PL!AB30:AM30) -> 880.54812
C23: Consolidated net income | D23: =SourceHistory!D20 -> 3864.3265 | E23: =SourceHistory!E20 -> 4269.1759 | F23: =SourceHistory!F20 -> 4076.302 | G23: =H1Actual!D23+(SUM(Monthly_PL!J31:O31)) -> 3929.6811 | H23: =SUM(Monthly_PL!P31:AA31) -> 4115.1327 | I23: =SUM(Monthly_PL!AB31:AM31) -> 4132.7821
C24: Parent net income | D24: =SourceHistory!D21 -> 3870.1354 | E24: =SourceHistory!E21 -> 4272.2046 | F24: =SourceHistory!F21 -> 4070.6327 | G24: =H1Actual!D24+(SUM(Monthly_PL!J32:O32)) -> 3923.2026 | H24: =SUM(Monthly_PL!P32:AA32) -> 4109.4094 | I24: =SUM(Monthly_PL!AB32:AM32) -> 4127.0342
C25: NCI net income | D25: =SourceHistory!D22 -> -5.8088851 | E25: =SourceHistory!E22 -> -3.0286538 | F25: =SourceHistory!F22 -> 5.6692836 | G25: =H1Actual!D25+(SUM(Monthly_PL!J33:O33)) -> 6.4784522 | H25: =SUM(Monthly_PL!P33:AA33) -> 5.723289 | I25: =SUM(Monthly_PL!AB33:AM33) -> 5.7478356
C28: Cash equivalents | D28: =SourceHistory!D29 -> 1332.1862 | E28: =SourceHistory!E29 -> 836.3144 | F28: =SourceHistory!F29 -> 721.04459 | G28: =Monthly_BS!O10 -> 2313.6962 | H28: =Monthly_BS!AA10 -> 2495.3179 | I28: =Monthly_BS!AM10 -> 2533.478
C29: Other monetary balances | D29: =SourceHistory!D32 -> 3411.5282 | E29: =SourceHistory!E32 -> 4184.0659 | F29: =SourceHistory!F32 -> 3446.2746 | G29: =Monthly_BS!O11 -> 3480.0156 | H29: =Monthly_BS!AA11 -> 3480.0156 | I29: =Monthly_BS!AM11 -> 3480.0156
C30: Receivables and contract assets | D30: =SourceHistory!D33 -> 270.11345 | E30: =SourceHistory!E33 -> 308.26795 | F30: =SourceHistory!F33 -> 327.3602 | G30: =Monthly_BS!O12 -> 326.36872 | H30: =Monthly_BS!AA12 -> 337.48118 | I30: =Monthly_BS!AM12 -> 349.17574
C31: Inventory | D31: =SourceHistory!D34 -> 1421.0781 | E31: =SourceHistory!E34 -> 1573.6728 | F31: =SourceHistory!F34 -> 1630.8262 | G31: =Monthly_BS!O13 -> 1364.4977 | H31: =Monthly_BS!AA13 -> 1404.5994 | I31: =Monthly_BS!AM13 -> 1452.0644
C32: PPE / CIP / property | D32: =SourceHistory!D35 -> 2792.7544 | E32: =SourceHistory!E35 -> 3541.0394 | F32: =SourceHistory!F35 -> 3593.7711 | G32: =Monthly_BS!O14 -> 3685.854 | H32: =Monthly_BS!AA14 -> 3877.8143 | I32: =Monthly_BS!AM14 -> 4067.5683
C33: Intangibles/deferred costs | D33: =SourceHistory!D36 -> 357.58366 | E33: =SourceHistory!E36 -> 368.71448 | F33: =SourceHistory!F36 -> 359.98872 | G33: =Monthly_BS!O15 -> 363.87075 | H33: =Monthly_BS!AA15 -> 392.02983 | I33: =Monthly_BS!AM15 -> 417.30554
C34: ROU | D34: =SourceHistory!D37 -> 18.802452 | E34: =SourceHistory!E37 -> 31.309235 | F34: =SourceHistory!F37 -> 25.219574 | G34: =Monthly_BS!O16 -> 10.095861 | H34: =Monthly_BS!AA16 -> 0 | I34: =Monthly_BS!AM16 -> 0
C35: Investments | D35: =SourceHistory!D38 -> 9735.2638 | E35: =SourceHistory!E38 -> 9225.0107 | F35: =SourceHistory!F38 -> 12068.473 | G35: =Monthly_BS!O17 -> 10538.02 | H35: =Monthly_BS!AA17 -> 10538.02 | I35: =Monthly_BS!AM17 -> 10538.02
C36: Other assets incl DTA and interest cohort | D36: =SourceHistory!D39 -> 422.89552 | E36: =SourceHistory!E39 -> 425.63951 | F36: =SourceHistory!F39 -> 383.28421 | G36: =Monthly_BS!O18+Monthly_BS!O19+Monthly_BS!O20 -> 484.72476 | H36: =Monthly_BS!AA18+Monthly_BS!AA19+Monthly_BS!AA20 -> 609.69943 | I36: =Monthly_BS!AM18+Monthly_BS!AM19+Monthly_BS!AM20 -> 737.06534
C38: Total assets | D38: =SourceHistory!D40 -> 19762.206 | E38: =SourceHistory!E40 -> 20494.034 | F38: =SourceHistory!F40 -> 22556.243 | G38: =Monthly_BS!O22 -> 22567.144 | H38: =Monthly_BS!AA22 -> 23134.978 | I38: =Monthly_BS!AM22 -> 23574.693
C40: Trade payables | D40: =SourceHistory!D41 -> 2056.6578 | E40: =SourceHistory!E41 -> 2392.0469 | F40: =SourceHistory!F41 -> 2455.3959 | G40: =Monthly_BS!O25 -> 2408.3982 | H40: =Monthly_BS!AA25 -> 2526.8622 | I40: =Monthly_BS!AM25 -> 2654.0833
C41: Customer advances | D41: =SourceHistory!D42 -> 528.49323 | E41: =SourceHistory!E42 -> 254.24995 | F41: =SourceHistory!F42 -> 592.67224 | G41: =Monthly_BS!O26 -> 590.67747 | H41: =Monthly_BS!AA26 -> 612.10871 | I41: =Monthly_BS!AM26 -> 634.66259
C42: Borrowings and leases | D42: =SourceHistory!D43 -> 1000.0467 | E42: =SourceHistory!E43 -> 314.62101 | F42: =SourceHistory!F43 -> 800.77562 | G42: =Monthly_BS!O27+Monthly_BS!O28 -> 934.87669 | H42: =Monthly_BS!AA27+Monthly_BS!AA28 -> 739.19139 | I42: =Monthly_BS!AM27+Monthly_BS!AM28 -> 554.76439
C43: Taxes payable | D43: =SourceHistory!D44 -> 311.19085 | E43: =SourceHistory!E44 -> 393.46764 | F43: =SourceHistory!F44 -> 444.24881 | G43: =Monthly_BS!O29+Monthly_BS!O30 -> 132.89806 | H43: =Monthly_BS!AA29+Monthly_BS!AA30 -> 132.89806 | I43: =Monthly_BS!AM29+Monthly_BS!AM30 -> 132.89806
C44: Other liabilities incl DTL | D44: =SourceHistory!D46 -> 1405.4056 | E44: =SourceHistory!E46 -> 1264.6687 | F44: =SourceHistory!F46 -> 1454.5799 | G44: =Monthly_BS!O31+Monthly_BS!O32 -> 1494.7807 | H44: =Monthly_BS!AA31+Monthly_BS!AA32 -> 1494.7807 | I44: =Monthly_BS!AM31+Monthly_BS!AM32 -> 1494.7807
C45: Finance company deposits | D45: =SourceHistory!D45 -> 0 | E45: =SourceHistory!E45 -> 0 | F45: =SourceHistory!F45 -> 0 | G45: =Monthly_BS!O33 -> 0 | H45: =Monthly_BS!AA33 -> 0 | I45: =Monthly_BS!AM33 -> 0
C47: Total liabilities | D47: =SourceHistory!D47 -> 5301.7942 | E47: =SourceHistory!E47 -> 4619.0541 | F47: =SourceHistory!F47 -> 5747.6725 | G47: =Monthly_BS!O35 -> 5561.6312 | H47: =Monthly_BS!AA35 -> 5505.8411 | I47: =Monthly_BS!AM35 -> 5471.1891
C49: Retained earnings | D49: =SourceHistory!D48 -> 9383.7349 | E49: =SourceHistory!E48 -> 10808.301 | F49: =SourceHistory!F48 -> 11553.52 | G49: =Monthly_BS!O38 -> 12041.695 | H49: =Monthly_BS!AA38 -> 12620.222 | I49: =Monthly_BS!AM38 -> 13048.788
C50: Share capital and reserves | D50: =D52-D49-D51 -> 5062.1871 | E50: =E52-E49-E51 -> 5057.8144 | F50: =F52-F49-F51 -> 5244.0948 | G50: =Monthly_BS!O39 -> 4946.3842 | H50: =Monthly_BS!AA39 -> 4991.5887 | I50: =Monthly_BS!AM39 -> 5036.7933
C51: NCI equity | D51: =SourceHistory!D49 -> 14.489582 | E51: =SourceHistory!E49 -> 8.8646797 | F51: =SourceHistory!F49 -> 10.954817 | G51: =Monthly_BS!O40 -> 17.433269 | H51: =Monthly_BS!AA40 -> 17.325951 | I51: =Monthly_BS!AM40 -> 17.922826
C52: Total equity | D52: =SourceHistory!D50 -> 14460.412 | E52: =SourceHistory!E50 -> 15874.98 | F52: =SourceHistory!F50 -> 16808.57 | G52: =Monthly_BS!O42 -> 17005.512 | H52: =Monthly_BS!AA42 -> 17629.137 | I52: =Monthly_BS!AM42 -> 18103.504
C53: BS difference | D53: =D38-D47-D52 -> 0 | E53: =E38-E47-E52 -> 0 | F53: =F38-F47-F52 -> 0 | G53: =Monthly_BS!O44 -> 0 | H53: =Monthly_BS!AA44 -> 0 | I53: =Monthly_BS!AM44 -> 0
...

Sheet Monthly_PL
C2: 公牛集团 Monthly_PL
C3: RMB million except stated units. H1 2026 actual aggregate is separate; monthly forecast begins July 2026.
D6: Not disclosed | E6: Not disclosed | F6: Not disclosed | G6: Not disclosed | H6: Not disclosed | I6: 2026H1A / 30-Jun | J6: Forecast | K6: Forecast | L6: Forecast | M6: Forecast | N6: Forecast | O6: Forecast | P6: Forecast | Q6: Forecast | R6: Forecast | S6: Forecast | T6: Forecast | U6: Forecast | V6: Forecast | W6: Forecast | X6: Forecast | Y6: Forecast | Z6: Forecast | AA6: Forecast | AB6: Forecast | AC6: Forecast | AD6: Forecast | AE6: Forecast | AF6: Forecast | AG6: Forecast | AH6: Forecast | AI6: Forecast | AJ6: Forecast | AK6: Forecast | AL6: Forecast | AM6: Forecast
D7: 46053 | E7: 46081 | F7: 46112 | G7: 46142 | H7: 46173 | I7: 46203 | J7: 46234 | K7: 46265 | L7: 46295 | M7: 46326 | N7: 46356 | O7: 46387 | P7: 46418 | Q7: 46446 | R7: 46477 | S7: 46507 | T7: 46538 | U7: 46568 | V7: 46599 | W7: 46630 | X7: 46660 | Y7: 46691 | Z7: 46721 | AA7: 46752 | AB7: 46783 | AC7: 46812 | AD7: 46843 | AE7: 46873 | AF7: 46904 | AG7: 46934 | AH7: 46965 | AI7: 46996 | AJ7: 47026 | AK7: 47057 | AL7: 47087 | AM7: 47118
C10: Revenue | I10: =H1Data!D83 -> 8393.7911 | J10: =Revenue!J40 -> 1356.5576 | K10: =Revenue!K40 -> 1356.5576 | L10: =Revenue!L40 -> 1356.5576 | M10: =Revenue!M40 -> 1356.5576 | N10: =Revenue!N40 -> 1356.5576 | O10: =Revenue!O40 -> 1356.5576 | P10: =Revenue!P40 -> 1448.8412 | Q10: =Revenue!Q40 -> 1448.8412 | ... AM10: =Revenue!AM40 -> 1457.5744
C11: Cost of goods released from FG | J11: =Production!J88 -> 934.96438 | K11: =Production!K88 -> 849.74845 | L11: =Production!L88 -> 811.31093 | M11: =Production!M88 -> 797.21891 | N11: =Production!N88 -> 788.59336 | O11: =Production!O88 -> 786.86144 | P11: =Production!P88 -> 841.68936 | Q11: =Production!Q88 -> 841.92267 | ... AM11: =Production!AM88 -> 870.90581
C12: Unabsorbed manufacturing cost | J12: =Production!J90 -> 0 | K12: =Production!K90 -> 0 | L12: =Production!L90 -> 0 | M12: =Production!M90 -> 0 | N12: =Production!N90 -> 0 | O12: =Production!O90 -> 0 | P12: =Production!P90 -> 0 | Q12: =Production!Q90 -> 0 | ... AM12: =Production!AM90 -> 0
C13: Other-business COGS | J13: =ExpenseDetail!J62 -> 0.45875339 | K13: =ExpenseDetail!K62 -> 0.45875339 | L13: =ExpenseDetail!L62 -> 0.45875339 | M13: =ExpenseDetail!M62 -> 0.45875339 | N13: =ExpenseDetail!N62 -> 0.45875339 | O13: =ExpenseDetail!O62 -> 0.45875339 | P13: =ExpenseDetail!P62 -> 2.8642473 | Q13: =ExpenseDetail!Q62 -> 2.8642473 | ... AM13: =ExpenseDetail!AM62 -> 0.45875339
C14: Total COGS | I14: =H1Data!D84 -> 4892.6546 | J14: =SUM(J11:J13) -> 935.42313 | K14: =SUM(K11:K13) -> 850.2072 | L14: =SUM(L11:L13) -> 811.76968 | M14: =SUM(M11:M13) -> 797.67766 | N14: =SUM(N11:N13) -> 789.05211 | O14: =SUM(O11:O13) -> 787.32019 | P14: =SUM(P11:P13) -> 844.5536 | Q14: =SUM(Q11:Q13) -> 844.78692 | ... AM14: =SUM(AM11:AM13) -> 871.36456
C15: Gross profit | I15: =H1Data!D83-H1Data!D84 -> 3501.1365 | J15: =J10-J14 -> 421.13451 | K15: =K10-K14 -> 506.35044 | L15: =L10-L14 -> 544.78796 | M15: =M10-M14 -> 558.87998 | N15: =N10-N14 -> 567.50553 | O15: =O10-O14 -> 569.23746 | P15: =P10-P14 -> 604.28759 | Q15: =Q10-Q14 -> 604.05427 | ... AM15: =AM10-AM14 -> 586.20989
C16: Gross margin | I16: =I15/I10 -> 0.41711027 | J16: =IF(J10=0,0,J15/J10) -> 0.31044351 | K16: =IF(K10=0,0,K15/K10) -> 0.37326128 | L16: =IF(L10=0,0,L15/L10) -> 0.40159588 | M16: =IF(M10=0,0,M15/M10) -> 0.41198396 | N16: =IF(N10=0,0,N15/N10) -> 0.41834236 | O16: =IF(O10=0,0,O15/O10) -> 0.41961907 | P16: =IF(P10=0,0,P15/P10) -> 0.41708338 | Q16: =IF(Q10=0,0,Q15/Q10) -> 0.41692235 | ... AM16: =IF(AM10=0,0,AM15/AM10) -> 0.40218178
C18: Selling expenses by nature | I18: =H1Data!D85 -> 584.11762 | J18: =ExpenseDetail!J17 -> 100.56811 | K18: =ExpenseDetail!K17 -> 100.56811 | L18: =ExpenseDetail!L17 -> 100.56811 | M18: =ExpenseDetail!M17 -> 100.56811 | N18: =ExpenseDetail!N17 -> 100.56811 | O18: =ExpenseDetail!O17 -> 100.56811 | P18: =ExpenseDetail!P17 -> 104.98134 | Q18: =ExpenseDetail!Q17 -> 104.98134 | ... AM18: =ExpenseDetail!AM17 -> 106.57812
C19: Administrative expenses by nature | I19: =H1Data!D86 -> 305.54311 | J19: =ExpenseDetail!J31 -> 60.136822 | K19: =ExpenseDetail!K31 -> 60.206488 | L19: =ExpenseDetail!L31 -> 60.276154 | M19: =ExpenseDetail!M31 -> 60.34582 | N19: =ExpenseDetail!N31 -> 60.415486 | O19: =ExpenseDetail!O31 -> 60.485152 | P19: =ExpenseDetail!P31 -> 61.767488 | Q19: =ExpenseDetail!Q31 -> 61.840637 | ... AM19: =ExpenseDetail!AM31 -> 64.322447
C20: R&D expenses by nature | I20: =H1Data!D87 -> 286.28158 | J20: =ExpenseDetail!J39 -> 54.911311 | K20: =ExpenseDetail!K39 -> 54.920963 | L20: =ExpenseDetail!L39 -> 54.930615 | M20: =ExpenseDetail!M39 -> 54.940268 | N20: =ExpenseDetail!N39 -> 54.94992 | O20: =ExpenseDetail!O39 -> 54.959572 | P20: =ExpenseDetail!P39 -> 57.125277 | Q20: =ExpenseDetail!Q39 -> 57.135412 | ... AM20: =ExpenseDetail!AM39 -> 58.531193
C21: Business taxes and surcharges | I21: =H1Data!D88 -> 76.482317 | J21: =ExpenseDetail!J61 -> 12.995537 | K21: =ExpenseDetail!K61 -> 12.995537 | L21: =ExpenseDetail!L61 -> 12.995537 | M21: =ExpenseDetail!M61 -> 12.995537 | N21: =ExpenseDetail!N61 -> 12.995537 | O21: =ExpenseDetail!O61 -> 12.995537 | P21: =ExpenseDetail!P61 -> 13.879594 | Q21: =ExpenseDetail!Q61 -> 13.879594 | ... AM21: =ExpenseDetail!AM61 -> 13.963257
C22: Credit impairment expense / (release) | I22: =-H1Data!D94 -> -0.11522692 | J22: =Receivables!J16 -> 0.56120476 | K22: =Receivables!K16 -> 0 | L22: =Receivables!L16 -> 0.90433539 | M22: =Receivables!M16 -> -0.90433539 | N22: =Receivables!N16 -> 0.90433539 | O22: =Receivables!O16 -> -0.90433539 | P22: =Receivables!P16 -> 1.8455967 | Q22: =Receivables!Q16 -> 3.1045348 | ... AM22: =Receivables!AM16 -> -0.97167721
C23: Asset impairment expense | I23: =H1Data!D95 -> 14.202526 | J23: =Assets!J103 -> 0 | K23: =Assets!K103 -> 0 | L23: =Assets!L103 -> 0 | M23: =Assets!M103 -> 0 | N23: =Assets!N103 -> 0 | O23: =Assets!O103 -> 0 | P23: =Assets!P103 -> 0 | Q23: =Assets!Q103 -> 0 | ... AM23: =Assets!AM103 -> 0
C24: Other pretax income / (expense) | I24: =H1Data!D92-H1Data!D96+H1Data!D97-H1Data!D98 -> 69.741335 | J24: =J10*Inputs!J80 -> 16.747859 | K24: =K10*Inputs!K80 -> 16.747859 | L24: =L10*Inputs!L80 -> 16.747859 | M24: =M10*Inputs!M80 -> 16.747859 | N24: =N10*Inputs!N80 -> 16.747859 | O24: =O10*Inputs!O80 -> 16.747859 | P24: =P10*Inputs!P80 -> 17.887178 | Q24: =Q10*Inputs!Q80 -> 17.887178 | ... AM24: =AM10*Inputs!AM80 -> 17.994997
C25: Investment cash income | I25: =H1Data!D93 -> 257.05764 | J25: =Funding!J59 -> 37.940387 | K25: =Funding!K59 -> 37.940387 | L25: =Funding!L59 -> 36.716504 | M25: =Funding!M59 -> 37.940387 | N25: =Funding!N59 -> 36.716504 | O25: =Funding!O59 -> 37.940387 | P25: =Funding!P59 -> 37.940387 | Q25: =Funding!Q59 -> 34.268737 | ... AM25: =Funding!AM59 -> 37.836725
C26: Investment FV gain/(loss) | J26: =Funding!J56 -> 0 | K26: =Funding!K56 -> 0 | L26: =Funding!L56 -> 0 | M26: =Funding!M56 -> 0 | N26: =Funding!N56 -> 0 | O26: =Funding!O56 -> 0 | P26: =Funding!P56 -> 0 | Q26: =Funding!Q56 -> 0 | ... AM26: =Funding!AM56 -> 0
C27: Monetary interest income | I27: =H1Data!D91 -> 45.193908 | J27: =Funding!J62 -> 8.6108962 | K27: =Funding!K62 -> 8.7649146 | L27: =Funding!L62 -> 9.1748728 | M27: =Funding!M62 -> 9.6570178 | N27: =Funding!N62 -> 9.6230686 | O27: =Funding!O62 -> 11.120156 | P27: =Funding!P62 -> 10.992375 | Q27: =Funding!Q62 -> 11.340942 | ... AM27: =Funding!AM62 -> 11.565178
C28: Finance costs excluding interest income | I28: =H1Data!D89+H1Data!D91 -> 10.648267 | J28: =Funding!J67+Funding!J49 -> 4.1053422 | K28: =Funding!K67+Funding!K49 -> 4.1010741 | L28: =Funding!L67+Funding!L49 -> 3.964651 | M28: =Funding!M67+Funding!M49 -> 4.0925379 | N28: =Funding!N67+Funding!N49 -> 3.9563902 | O28: =Funding!O67+Funding!O49 -> 4.0840017 | P28: =Funding!P67+Funding!P49 -> 4.0797336 | Q28: =Funding!Q67+Funding!Q49 -> 3.6810656 | ... AM28: =Funding!AM67+Funding!AM49 -> 2.4153845
C29: Profit before tax | I29: =H1Data!D99 -> 2595.9692 | J29: =J15-SUM(J18:J23)+SUM(J24:J27)-J28 -> 251.15533 | K29: =K15-SUM(K18:K23)+SUM(K24:K27)-K28 -> 337.01144 | L29: =L15-SUM(L18:L23)+SUM(L24:L27)-L28 -> 373.7878 | M29: =M15-SUM(M18:M23)+SUM(M24:M27)-M28 -> 391.18732 | N29: =N15-SUM(N18:N23)+SUM(N24:N27)-N28 -> 396.80319 | O29: =O15-SUM(O18:O23)+SUM(O24:O27)-O28 -> 402.85783 | P29: =P15-SUM(P18:P23)+SUM(P24:P27)-P28 -> 427.4285 | Q29: =Q15-SUM(Q18:Q23)+SUM(Q24:Q27)-Q28 -> 422.92854 | ... AM29: =AM15-SUM(AM18:AM23)+SUM(AM24:AM27)-AM28 -> 408.76807
C30: Income-tax expense | I30: =H1Data!D100 -> 440.96975 | J30: =TaxEquity!J24 -> 44.113264 | K30: =TaxEquity!K24 -> 59.193146 | L30: =TaxEquity!L24 -> 65.652596 | M30: =TaxEquity!M24 -> 68.708671 | N30: =TaxEquity!N24 -> 69.695051 | O30: =TaxEquity!O24 -> 70.758495 | P30: =TaxEquity!P24 -> 75.074122 | Q30: =TaxEquity!Q24 -> 74.283744 | ... AM30: =TaxEquity!AM24 -> 71.796578
C31: Consolidated net income | I31: =H1Data!D101 -> 2154.9994 | J31: =J29-J30 -> 207.04207 | K31: =K29-K30 -> 277.81829 | L31: =L29-L30 -> 308.1352 | M31: =M29-M30 -> 322.47864 | N31: =N29-N30 -> 327.10814 | O31: =O29-O30 -> 332.09933 | P31: =P29-P30 -> 352.35438 | Q31: =Q29-Q30 -> 348.6448 | ... AM31: =AM29-AM30 -> 336.97149
C32: Parent net income | I32: =H1Data!D102 -> 2150.9892 | J32: =J31-J33 -> 206.75412 | K32: =K31-K33 -> 277.4319 | L32: =L31-L33 -> 307.70665 | M32: =M31-M33 -> 322.03014 | N32: =N31-N33 -> 326.6532 | O32: =O31-O33 -> 331.63745 | P32: =P31-P33 -> 351.86433 | Q32: =Q31-Q33 -> 348.15991 | ... AM32: =AM31-AM33 -> 336.50283
C33: NCI net income | I33: =H1Data!D103 -> 4.0102411 | J33: =J31*SourceHistory!F22/SourceHistory!F20 -> 0.28795222 | K33: =K31*SourceHistory!F22/SourceHistory!F20 -> 0.38638714 | L33: =L31*SourceHistory!F22/SourceHistory!F20 -> 0.42855163 | M33: =M31*SourceHistory!F22/SourceHistory!F20 -> 0.44850035 | N33: =N31*SourceHistory!F22/SourceHistory!F20 -> 0.45493901 | O33: =O31*SourceHistory!F22/SourceHistory!F20 -> 0.46188072 | P33: =P31*SourceHistory!F22/SourceHistory!F20 -> 0.49005125 | Q33: =Q31*SourceHistory!F22/SourceHistory!F20 -> 0.48489201 | R33: =R31*SourceHistory!F22/SourceHistory!F20 -> 0.49181979 | S33: =S31*SourceHistory!F22/SourceHistory!F20 -> 0.48537355 | T33: =T31*SourceHistory!F22/SourceHistory!F20 -> 0.48946009 | U33: =U31*SourceHistory!F22/SourceHistory!F20 -> 0.48701434 | V33: =V31*SourceHistory!F22/SourceHistory!F20 -> 0.46590835 | W33: =W31*SourceHistory!F22/SourceHistory!F20 -> 0.46387626 | X33: =X31*SourceHistory!F22/SourceHistory!F20 -> 0.46440787 | Y33: =Y31*SourceHistory!F22/SourceHistory!F20 -> 0.46713397 | Z33: =Z31*SourceHistory!F22/SourceHistory!F20 -> 0.46497742 | AA33: =AA31*SourceHistory!F22/SourceHistory!F20 -> 0.46837406 | AB33: =AB31*SourceHistory!F22/SourceHistory!F20 -> 0.49437733 | AC33: =AC31*SourceHistory!F22/SourceHistory!F20 -> 0.48999091 | AD33: =AD31*SourceHistory!F22/SourceHistory!F20 -> 0.49370187 | AE33: =AE31*SourceHistory!F22/SourceHistory!F20 -> 0.48836538 | AF33: =AF31*SourceHistory!F22/SourceHistory!F20 -> 0.49201019 | AG33: =AG31*SourceHistory!F22/SourceHistory!F20 -> 0.48934677 | AH33: =AH31*SourceHistory!F22/SourceHistory!F20 -> 0.46779887 | AI33: =AI31*SourceHistory!F22/SourceHistory!F20 -> 0.46562969 | AJ33: =AJ31*SourceHistory!F22/SourceHistory!F20 -> 0.46508996 | AK33: =AK31*SourceHistory!F22/SourceHistory!F20 -> 0.46760275 | AL33: =AL31*SourceHistory!F22/SourceHistory!F20 -> 0.46526501 | AM33: =AM31*SourceHistory!F22/SourceHistory!F20 -> 0.46865687
C35: Total D&A (memo) | J35: =Assets!J100 -> 26.380476 | K35: =Assets!K100 -> 26.591641 | L35: =Assets!L100 -> 26.802806 | M35: =Assets!M100 -> 27.013971 | N35: =Assets!N100 -> 27.225136 | O35: =Assets!O100 -> 27.436302 | P35: =Assets!P100 -> 27.647467 | Q35: =Assets!Q100 -> 27.86919 | ... AM35: =Assets!AM100 -> 31.609107
C36: EBITDA calculation proxy | J36: =J29+J28-J27+J35 -> 273.03025 | K36: =K29+K28-K27+K35 -> 358.93924 | L36: =L29+L28-L27+L35 -> 395.38038 | M36: =M29+M28-M27+M35 -> 412.63681 | N36: =N29+N28-N27+N35 -> 418.36165 | O36: =O29+O28-O27+O35 -> 423.25797 | P36: =P29+P28-P27+P35 -> 448.16332 | Q36: =Q29+Q28-Q27+Q35 -> 443.13786 | ... AM36: =AM29+AM28-AM27+AM35 -> 431.22738
C37: H1 finance costs exclude interest income and include other finance charges; forecast costs here are loan/lease/RCF interest. H1 asset impairment includes inventory and contract-performance costs. Forecast other pretax income uses a separately stated cash assumption.
C41: EBITDA is a calculation proxy, not an issuer-defined KPI; it includes investment/other pretax income. Monthly positive-profit tax accrual does not model entity-level loss carryforwards. Interim revenue anchors do not make the monthly P&L an actual management account.

Sheet Monthly_BS
C2: 公牛集团 Monthly_BS
C3: RMB million except stated units. H1 2026 actual aggregate is separate; monthly forecast begins July 2026.
D6: Not disclosed | E6: Not disclosed | F6: Not disclosed | G6: Not disclosed | H6: Not disclosed | I6: 2026H1A / 30-Jun | J6: Forecast | K6: Forecast | L6: Forecast | M6: Forecast | N6: Forecast | O6: Forecast | P6: Forecast | Q6: Forecast | R6: Forecast | S6: Forecast | T6: Forecast | U6: Forecast | V6: Forecast | W6: Forecast | X6: Forecast | Y6: Forecast | Z6: Forecast | AA6: Forecast | AB6: Forecast | AC6: Forecast | AD6: Forecast | AE6: Forecast | AF6: Forecast | AG6: Forecast | AH6: Forecast | AI6: Forecast | AJ6: Forecast | AK6: Forecast | AL6: Forecast | AM6: Forecast
D7: 46053 | E7: 46081 | F7: 46112 | G7: 46142 | H7: 46173 | I7: 46203 | J7: 46234 | K7: 46265 | L7: 46295 | M7: 46326 | N7: 46356 | O7: 46387 | P7: 46418 | Q7: 46446 | R7: 46477 | S7: 46507 | T7: 46538 | U7: 46568 | V7: 46599 | W7: 46630 | X7: 46660 | Y7: 46691 | Z7: 46721 | AA7: 46752 | AB7: 46783 | AC7: 46812 | AD7: 46843 | AE7: 46873 | AF7: 46904 | AG7: 46934 | AH7: 46965 | AI7: 46996 | AJ7: 47026 | AK7: 47057 | AL7: 47087 | AM7: 47118
C10: Cash and cash equivalents | I10: =H1Data!D9 -> 1058.4987 | J10: =Monthly_CF!J51 -> 1139.6766 | K10: =Monthly_CF!K51 -> 1516.9441 | L10: =Monthly_CF!L51 -> 1609.8743 | M10: =Monthly_CF!M51 -> 1761.0473 | N10: =Monthly_CF!N51 -> 2381.0452 | O10: =Monthly_CF!O51 -> 2313.6962 | P10: =Monthly_CF!P51 -> 3137.8529 | Q10: =Monthly_CF!Q51 -> 3861.9133 | ... AM10: =Monthly_CF!AM51 -> 2533.478
C11: Other monetary balances outside CE | I11: =H1Data!D11 -> 3480.0156 | J11: =H1Data!D11 -> 3480.0156 | K11: =H1Data!D11 -> 3480.0156 | L11: =H1Data!D11 -> 3480.0156 | M11: =H1Data!D11 -> 3480.0156 | N11: =H1Data!D11 -> 3480.0156 | O11: =H1Data!D11 -> 3480.0156 | P11: =H1Data!D11 -> 3480.0156 | Q11: =H1Data!D11 -> 3480.0156 | R11: =H1Data!D11 -> 3480.0156 | S11: =H1Data!D11 -> 3480.0156 | T11: =H1Data!D11 -> 3480.0156 | U11: =H1Data!D11 -> 3480.0156 | V11: =H1Data!D11 -> 3480.0156 | W11: =H1Data!D11 -> 3480.0156 | X11: =H1Data!D11 -> 3480.0156 | Y11: =H1Data!D11 -> 3480.0156 | Z11: =H1Data!D11 -> 3480.0156 | AA11: =H1Data!D11 -> 3480.0156 | AB11: =H1Data!D11 -> 3480.0156 | AC11: =H1Data!D11 -> 3480.0156 | AD11: =H1Data!D11 -> 3480.0156 | AE11: =H1Data!D11 -> 3480.0156 | AF11: =H1Data!D11 -> 3480.0156 | AG11: =H1Data!D11 -> 3480.0156 | AH11: =H1Data!D11 -> 3480.0156 | AI11: =H1Data!D11 -> 3480.0156 | AJ11: =H1Data!D11 -> 3480.0156 | AK11: =H1Data!D11 -> 3480.0156 | AL11: =H1Data!D11 -> 3480.0156 | AM11: =H1Data!D11 -> 3480.0156
C12: Trade receivables net / bills / contract assets | I12: =H1Data!D17+H1Data!D16+H1Data!D19 -> 330.98513 | J12: =Receivables!J19 -> 326.36872 | K12: =Receivables!K19 -> 326.36872 | L12: =Receivables!L19 -> 336.57792 | M12: =Receivables!M19 -> 326.36872 | N12: =Receivables!N19 -> 336.57792 | O12: =Receivables!O19 -> 326.36872 | P12: =Receivables!P19 -> 347.20399 | Q12: =Receivables!Q19 -> 382.25164 | ... AM12: =Receivables!AM19 -> 349.17574
C13: Inventories by category | I13: =H1Data!D22 -> 1636.9642 | J13: =Inventory!J30 -> 1485.8057 | K13: =Inventory!K30 -> 1418.6729 | L13: =Inventory!L30 -> 1415.2734 | M13: =Inventory!M30 -> 1373.4713 | N13: =Inventory!N30 -> 1395.6786 | O13: =Inventory!O30 -> 1364.4977 | P13: =Inventory!P30 -> 1424.0643 | Q13: =Inventory!Q30 -> 1512.0266 | ... AM13: =Inventory!AM30 -> 1452.0644
C14: PPE/CIP/investment property group | I14: =H1Data!D24+H1Data!D25 -> 3591.9678 | J14: =Assets!J99 -> 3608.0523 | K14: =Assets!K99 -> 3623.962 | L14: =Assets!L99 -> 3639.6971 | M14: =Assets!M99 -> 3655.2574 | N14: =Assets!N99 -> 3670.6431 | O14: =Assets!O99 -> 3685.854 | P14: =Assets!P99 -> 3702.8596 | Q14: =Assets!Q99 -> 3719.6817 | ... AM14: =Assets!AM99 -> 4067.5683
C15: Intangible and deferred cost group | I15: =H1Data!D27+H1Data!D28 -> 349.0746 | J15: =Assets!J76 -> 351.63179 | K15: =Assets!K76 -> 354.15252 | L15: =Assets!L76 -> 356.63678 | M15: =Assets!M76 -> 359.08457 | N15: =Assets!N76 -> 361.49589 | O15: =Assets!O76 -> 363.87075 | P15: =Assets!P76 -> 366.42794 | Q15: =Assets!Q76 -> 368.94685 | ... AM15: =Assets!AM76 -> 417.30554
C16: ROU assets | I16: =H1Data!D26 -> 17.655538 | J16: =Assets!J88 -> 16.395592 | K16: =Assets!K88 -> 15.135646 | L16: =Assets!L88 -> 13.8757 | M16: =Assets!M88 -> 12.615754 | N16: =Assets!N88 -> 11.355807 | O16: =Assets!O88 -> 10.095861 | P16: =Assets!P88 -> 8.835915 | Q16: =Assets!Q88 -> 7.5759688 | ... AM16: =Assets!AM88 -> 0
C17: Financial investments | I17: =H1Data!D12 -> 10538.02 | J17: =Funding!J58 -> 10538.02 | K17: =Funding!K58 -> 10538.02 | L17: =Funding!L58 -> 10538.02 | M17: =Funding!M58 -> 10538.02 | N17: =Funding!N58 -> 10538.02 | O17: =Funding!O58 -> 10538.02 | P17: =Funding!P58 -> 10538.02 | Q17: =Funding!Q58 -> 10538.02 | ... AM17: =Funding!AM58 -> 10538.02
C18: Named other assets excluding DTA | I18: =H1Data!D20+H1Data!D21+H1Data!D23+H1Data!D30 -> 186.15963 | J18: =OtherBalances!J19 -> 186.15963 | K18: =OtherBalances!K19 -> 186.15963 | L18: =OtherBalances!L19 -> 186.15963 | M18: =OtherBalances!M19 -> 186.15963 | N18: =OtherBalances!N19 -> 186.15963 | O18: =OtherBalances!O19 -> 186.15963 | P18: =OtherBalances!P19 -> 186.15963 | Q18: =OtherBalances!Q19 -> 186.15963 | ... AM18: =OtherBalances!AM19 -> 186.15963
C19: Post-2025 accrued interest cohort | J19: =OtherBalances!J45 -> 7.9957033 | K19: =OtherBalances!K45 -> 16.134421 | L19: =OtherBalances!L45 -> 24.653809 | M19: =OtherBalances!M45 -> 33.620895 | N19: =OtherBalances!N45 -> 42.556458 | O19: =OtherBalances!O45 -> 52.88215 | P19: =OtherBalances!P45 -> 63.089191 | Q19: =OtherBalances!Q45 -> 73.619896 | ... AM19: =OtherBalances!AM45 -> 305.22273
C20: DTA | I20: =H1Data!D29 -> 245.68298 | J20: =TaxEquity!J18 -> 245.68298 | K20: =TaxEquity!K18 -> 245.68298 | L20: =TaxEquity!L18 -> 245.68298 | M20: =TaxEquity!M18 -> 245.68298 | N20: =TaxEquity!N18 -> 245.68298 | O20: =TaxEquity!O18 -> 245.68298 | P20: =TaxEquity!P18 -> 245.68298 | Q20: =TaxEquity!Q18 -> 245.68298 | ... AM20: =TaxEquity!AM18 -> 245.68298
C22: Total assets | I22: =H1Data!D31 -> 21435.024 | J22: =SUM(J10:J20) -> 21385.805 | K22: =SUM(K10:K20) -> 21721.249 | L22: =SUM(L10:L20) -> 21846.467 | M22: =SUM(M10:M20) -> 21971.344 | N22: =SUM(N10:N20) -> 22649.231 | O22: =SUM(O10:O20) -> 22567.144 | P22: =SUM(P10:P20) -> 23500.212 | Q22: =SUM(Q10:Q20) -> 24375.894 | ... AM22: =SUM(AM10:AM20) -> 23574.693
C25: Goods/construction/expense payables | I25: =H1Data!D36 -> 2564.4435 | J25: =Receivables!J30 -> 2502.1074 | K25: =Receivables!K30 -> 2497.8895 | L25: =Receivables!L30 -> 2657.6696 | M25: =Receivables!M30 -> 2408.3982 | N25: =Receivables!N30 -> 2667.1426 | O25: =Receivables!O30 -> 2408.3982 | P25: =Receivables!P30 -> 2871.2055 | Q25: =Receivables!Q30 -> 3253.7166 | ... AM25: =Receivables!AM30 -> 2654.0833
C26: Customer advances | I26: =H1Data!D40 -> 831.36657 | J26: =Receivables!J40 -> 590.67747 | K26: =Receivables!K40 -> 590.67747 | L26: =Receivables!L40 -> 610.36672 | M26: =Receivables!M40 -> 590.67747 | N26: =Receivables!N40 -> 610.36672 | O26: =Receivables!O40 -> 590.67747 | P26: =Receivables!P40 -> 630.85992 | Q26: =Receivables!Q40 -> 698.45205 | ... AM26: =Receivables!AM40 -> 634.66259
C27: Loan principal and historic accrued interest | I27: =H1Data!D32+H1Data!D47 -> 923.61839 | J27: =Funding!J68 -> 923.61839 | K27: =Funding!K68 -> 923.61839 | L27: =Funding!L68 -> 923.61839 | M27: =Funding!M68 -> 923.61839 | N27: =Funding!N68 -> 923.61839 | O27: =Funding!O68 -> 923.61839 | P27: =Funding!P68 -> 923.61839 | Q27: =Funding!Q68 -> 923.61839 | ... AM27: =Funding!AM68 -> 554.76439
C28: Lease liabilities | I28: =H1Data!D45+H1Data!D48 -> 17.958773 | J28: =Funding!J48 -> 16.842029 | K28: =Funding!K48 -> 15.725284 | L28: =Funding!L48 -> 14.608539 | M28: =Funding!M48 -> 13.491795 | N28: =Funding!N48 -> 12.37505 | O28: =Funding!O48 -> 11.258306 | P28: =Funding!P48 -> 10.141561 | Q28: =Funding!Q48 -> 9.0248167 | ... AM28: =Funding!AM48 -> 0
C29: Income-tax payable | I29: =H1Data!D43 -> 261.72983 | J29: =TaxEquity!J13 -> 305.84309 | K29: =TaxEquity!K13 -> 365.03624 | L29: =TaxEquity!L13 -> 0 | M29: =TaxEquity!M13 -> 68.708671 | N29: =TaxEquity!N13 -> 138.40372 | O29: =TaxEquity!O13 -> 0 | P29: =TaxEquity!P13 -> 75.074122 | Q29: =TaxEquity!Q13 -> 149.35787 | ... AM29: =TaxEquity!AM13 -> 0
C30: Other taxes payable | I30: =H1Data!D42-H1Data!D43 -> 132.89806 | J30: =TaxEquity!J26 -> 132.89806 | K30: =TaxEquity!K26 -> 132.89806 | L30: =TaxEquity!L26 -> 132.89806 | M30: =TaxEquity!M26 -> 132.89806 | N30: =TaxEquity!N26 -> 132.89806 | O30: =TaxEquity!O26 -> 132.89806 | P30: =TaxEquity!P26 -> 132.89806 | Q30: =TaxEquity!Q26 -> 132.89806 | ... AM30: =TaxEquity!AM26 -> 132.89806
C31: Named other liabilities excluding DTL | I31: =H1Data!D41+H1Data!D44+H1Data!D46+H1Data!D49+H1Data!D51+H1Data!D35 -> 1408.6786 | J31: =OtherBalances!J39 -> 1408.6786 | K31: =OtherBalances!K39 -> 1408.6786 | L31: =OtherBalances!L39 -> 1408.6786 | M31: =OtherBalances!M39 -> 1408.6786 | N31: =OtherBalances!N39 -> 1408.6786 | O31: =OtherBalances!O39 -> 1408.6786 | P31: =OtherBalances!P39 -> 1408.6786 | Q31: =OtherBalances!Q39 -> 1408.6786 | ... AM31: =OtherBalances!AM39 -> 1408.6786
C32: DTL | I32: =H1Data!D50 -> 86.102097 | J32: =TaxEquity!J22 -> 86.102097 | K32: =TaxEquity!K22 -> 86.102097 | L32: =TaxEquity!L22 -> 86.102097 | M32: =TaxEquity!M22 -> 86.102097 | N32: =TaxEquity!N22 -> 86.102097 | O32: =TaxEquity!O22 -> 86.102097 | P32: =TaxEquity!P22 -> 86.102097 | Q32: =TaxEquity!Q22 -> 86.102097 | ... AM32: =TaxEquity!AM22 -> 86.102097
C33: Finance-company deposits source balance | J33: =SourceHistory!F45 -> 0 | K33: =SourceHistory!F45 -> 0 | L33: =SourceHistory!F45 -> 0 | M33: =SourceHistory!F45 -> 0 | N33: =SourceHistory!F45 -> 0 | O33: =SourceHistory!F45 -> 0 | P33: =SourceHistory!F45 -> 0 | Q33: =SourceHistory!F45 -> 0 | R33: =SourceHistory!F45 -> 0 | S33: =SourceHistory!F45 -> 0 | T33: =SourceHistory!F45 -> 0 | U33: =SourceHistory!F45 -> 0 | V33: =SourceHistory!F45 -> 0 | W33: =SourceHistory!F45 -> 0 | X33: =SourceHistory!F45 -> 0 | Y33: =SourceHistory!F45 -> 0 | Z33: =SourceHistory!F45 -> 0 | AA33: =SourceHistory!F45 -> 0 | AB33: =SourceHistory!F45 -> 0 | AC33: =SourceHistory!F45 -> 0 | AD33: =SourceHistory!F45 -> 0 | AE33: =SourceHistory!F45 -> 0 | AF33: =SourceHistory!F45 -> 0 | AG33: =SourceHistory!F45 -> 0 | AH33: =SourceHistory!F45 -> 0 | AI33: =SourceHistory!F45 -> 0 | AJ33: =SourceHistory!F45 -> 0 | AK33: =SourceHistory!F45 -> 0 | AL33: =SourceHistory!F45 -> 0 | AM33: =SourceHistory!F45 -> 0
C35: Total liabilities | I35: =H1Data!D52 -> 6226.7958 | J35: =SUM(J25:J33) -> 5966.7671 | K35: =SUM(K25:K33) -> 6020.6256 | L35: =SUM(L25:L33) -> 5833.942 | M35: =SUM(M25:M33) -> 5632.5734 | N35: =SUM(N25:N33) -> 5979.5852 | O35: =SUM(O25:O33) -> 5561.6312 | P35: =SUM(P25:P33) -> 6138.5783 | Q35: =SUM(Q25:Q33) -> 6661.8485 | ... AM35: =SUM(AM25:AM33) -> 5471.1891
C38: Retained earnings | I38: =H1Data!D58 -> 10269.482 | J38: =TaxEquity!J35 -> 10476.236 | K38: =TaxEquity!K35 -> 10753.668 | L38: =TaxEquity!L35 -> 11061.374 | M38: =TaxEquity!M35 -> 11383.404 | N38: =TaxEquity!N35 -> 11710.058 | O38: =TaxEquity!O35 -> 12041.695 | P38: =TaxEquity!P35 -> 12393.559 | Q38: =TaxEquity!Q35 -> 12741.719 | ... AM38: =TaxEquity!AM35 -> 13048.788
C39: Share capital and reserves | I39: =H1Data!D53+H1Data!D54-H1Data!D55+H1Data!D56+H1Data!D57 -> 4923.7819 | J39: =TaxEquity!J46 -> 4927.549 | K39: =TaxEquity!K46 -> 4931.316 | L39: =TaxEquity!L46 -> 4935.0831 | M39: =TaxEquity!M46 -> 4938.8501 | N39: =TaxEquity!N46 -> 4942.6171 | O39: =TaxEquity!O46 -> 4946.3842 | P39: =TaxEquity!P46 -> 4950.1512 | Q39: =TaxEquity!Q46 -> 4953.9183 | ... AM39: =TaxEquity!AM46 -> 5036.7933
C40: NCI equity | I40: =H1Data!D59 -> 14.965058 | J40: =TaxEquity!J39 -> 15.25301 | K40: =TaxEquity!K39 -> 15.639397 | L40: =TaxEquity!L39 -> 16.067949 | M40: =TaxEquity!M39 -> 16.516449 | N40: =TaxEquity!N39 -> 16.971388 | O40: =TaxEquity!O39 -> 17.433269 | P40: =TaxEquity!P39 -> 17.92332 | Q40: =TaxEquity!Q39 -> 18.408212 | ... AM40: =TaxEquity!AM39 -> 17.922826
C42: Total equity | I42: =H1Data!D60 -> 15208.228 | J42: =SUM(J38:J40) -> 15419.038 | K42: =SUM(K38:K40) -> 15700.623 | L42: =SUM(L38:L40) -> 16012.525 | M42: =SUM(M38:M40) -> 16338.771 | N42: =SUM(N38:N40) -> 16669.646 | O42: =SUM(O38:O40) -> 17005.512 | P42: =SUM(P38:P40) -> 17361.634 | Q42: =SUM(Q38:Q40) -> 17714.046 | ... AM42: =SUM(AM38:AM40) -> 18103.504
C43: Total liabilities and equity | I43: =H1Data!D52+H1Data!D60 -> 21435.024 | J43: =J35+J42 -> 21385.805 | K43: =K35+K42 -> 21721.249 | L43: =L35+L42 -> 21846.467 | M43: =M35+M42 -> 21971.344 | N43: =N35+N42 -> 22649.231 | O43: =O35+O42 -> 22567.144 | P43: =P35+P42 -> 23500.212 | Q43: =Q35+Q42 -> 24375.894 | ... AM43: =AM35+AM42 -> 23574.693
C44: Balance-sheet difference | I44: =I22-I43 -> 0 | J44: =J22-J43 -> 0 | K44: =K22-K43 -> 0 | L44: =L22-L43 -> 0 | M44: =M22-M43 -> 0 | N44: =N22-N43 -> 0 | O44: =O22-O43 -> 0 | P44: =P22-P43 -> 0 | ... AM44: =AM22-AM43 -> 0
C46: Cash-to-CFS difference | I46: =I10-H1Actual!D61 -> 0 | J46: =J10-Monthly_CF!J51 -> 0 | K46: =K10-Monthly_CF!K51 -> 0 | L46: =L10-Monthly_CF!L51 -> 0 | M46: =M10-Monthly_CF!M51 -> 0 | N46: =N10-Monthly_CF!N51 -> 0 | O46: =O10-Monthly_CF!O51 -> 0 | P46: =P10-Monthly_CF!P51 -> 0 | Q46: =Q10-Monthly_CF!Q51 -> 0 | ... AM46: =AM10-Monthly_CF!AM51 -> 0

Sheet Monthly_CF
C2: 公牛集团 Monthly_CF
C3: RMB million except stated units. H1 2026 actual aggregate is separate; monthly forecast begins July 2026.
D6: Not disclosed | E6: Not disclosed | F6: Not disclosed | G6: Not disclosed | H6: Not disclosed | I6: 2026H1A / 30-Jun | J6: Forecast | K6: Forecast | L6: Forecast | M6: Forecast | N6: Forecast | O6: Forecast | P6: Forecast | Q6: Forecast | R6: Forecast | S6: Forecast | T6: Forecast | U6: Forecast | V6: Forecast | W6: Forecast | X6: Forecast | Y6: Forecast | Z6: Forecast | AA6: Forecast | AB6: Forecast | AC6: Forecast | AD6: Forecast | AE6: Forecast | AF6: Forecast | AG6: Forecast | AH6: Forecast | AI6: Forecast | AJ6: Forecast | AK6: Forecast | AL6: Forecast | AM6: Forecast
D7: 46053 | E7: 46081 | F7: 46112 | G7: 46142 | H7: 46173 | I7: 46203 | J7: 46234 | K7: 46265 | L7: 46295 | M7: 46326 | N7: 46356 | O7: 46387 | P7: 46418 | Q7: 46446 | R7: 46477 | S7: 46507 | T7: 46538 | U7: 46568 | V7: 46599 | W7: 46630 | X7: 46660 | Y7: 46691 | Z7: 46721 | AA7: 46752 | AB7: 46783 | AC7: 46812 | AD7: 46843 | AE7: 46873 | AF7: 46904 | AG7: 46934 | AH7: 46965 | AI7: 46996 | AJ7: 47026 | AK7: 47057 | AL7: 47087 | AM7: 47118
C9: Direct operating cash flow
C10: Cash collections incl customer advances | J10: =Receivables!J43 -> 1119.9238 | K10: =Receivables!K43 -> 1356.5576 | L10: =Receivables!L43 -> 1365.1334 | M10: =Receivables!M43 -> 1347.9819 | N10: =Receivables!N43 -> 1365.1334 | O10: =Receivables!O43 -> 1347.9819 | P10: =Receivables!P43 -> 1466.3428 | Q10: =Receivables!Q43 -> 1478.2811 | ... AM10: =Receivables!AM43 -> 1448.3601
C11: Cash other pretax income | J11: =Monthly_PL!J24 -> 16.747859 | K11: =Monthly_PL!K24 -> 16.747859 | L11: =Monthly_PL!L24 -> 16.747859 | M11: =Monthly_PL!M24 -> 16.747859 | N11: =Monthly_PL!N24 -> 16.747859 | O11: =Monthly_PL!O24 -> 16.747859 | P11: =Monthly_PL!P24 -> 17.887178 | Q11: =Monthly_PL!Q24 -> 17.887178 | ... AM11: =Monthly_PL!AM24 -> 17.994997
C12: Cash interest income received | J12: =Funding!J63 -> 0.61519284 | K12: =Funding!K63 -> 0.62619647 | L12: =Funding!L63 -> 0.65548533 | M12: =Funding!M63 -> 0.68993147 | N12: =Funding!N63 -> 0.68750601 | O12: =Funding!O63 -> 0.79446322 | P12: =Funding!P63 -> 0.78533409 | Q12: =Funding!Q63 -> 0.81023694 | ... AM12: =Funding!AM63 -> 0.8262572
C14: Cash payments to material suppliers | J14: =-1*Receivables!J27 -> -713.10258 | K14: =-1*Receivables!K27 -> -653.77635 | L14: =-1*Receivables!L27 -> -513.11069 | M14: =-1*Receivables!M27 -> -873.19893 | N14: =-1*Receivables!N27 -> -416.77208 | O14: =-1*Receivables!O27 -> -882.67191 | P14: =-1*Receivables!P27 -> -293.67123 | Q14: =-1*Receivables!Q27 -> -399.71144 | ... AM14: =-1*Receivables!AM27 -> -985.13601
C15: Production payroll cash | J15: =-1*Production!J87 -> -47.012986 | K15: =-1*Production!K87 -> -47.012986 | L15: =-1*Production!L87 -> -47.012986 | M15: =-1*Production!M87 -> -47.012986 | N15: =-1*Production!N87 -> -47.012986 | O15: =-1*Production!O87 -> -47.012986 | P15: =-1*Production!P87 -> -48.423375 | Q15: =-1*Production!Q87 -> -48.423375 | ... AM15: =-1*Production!AM87 -> -49.876076
C16: Cash manufacturing overhead | J16: =-1*Production!J86 -> -69.554971 | K16: =-1*Production!K86 -> -69.440885 | L16: =-1*Production!L86 -> -71.272514 | M16: =-1*Production!M86 -> -67.609256 | N16: =-1*Production!N86 -> -71.272514 | O16: =-1*Production!O86 -> -67.609256 | P16: =-1*Production!P86 -> -79.091612 | Q16: =-1*Production!Q86 -> -81.838098 | ... AM16: =-1*Production!AM86 -> -75.244571
C17: Additional WIP cash cost | J17: =-1*Inventory!J17 -> 0 | K17: =-1*Inventory!K17 -> 0 | L17: =-1*Inventory!L17 -> 0 | M17: =-1*Inventory!M17 -> 0 | N17: =-1*Inventory!N17 -> 0 | O17: =-1*Inventory!O17 -> 0 | P17: =-1*Inventory!P17 -> 0 | Q17: =-1*Inventory!Q17 -> 0 | ... AM17: =-1*Inventory!AM17 -> 0
C18: Cash selling/admin/R&D | J18: =-1*ExpenseDetail!J60 -> -201.94014 | K18: =-1*ExpenseDetail!K60 -> -201.94014 | L18: =-1*ExpenseDetail!L60 -> -201.94014 | M18: =-1*ExpenseDetail!M60 -> -201.94014 | N18: =-1*ExpenseDetail!N60 -> -201.94014 | O18: =-1*ExpenseDetail!O60 -> -201.94014 | P18: =-1*ExpenseDetail!P60 -> -209.72209 | Q18: =-1*ExpenseDetail!Q60 -> -209.72209 | ... AM18: =-1*ExpenseDetail!AM60 -> -213.79168
C19: Business taxes and surcharges cash | J19: =-1*ExpenseDetail!J61 -> -12.995537 | K19: =-1*ExpenseDetail!K61 -> -12.995537 | L19: =-1*ExpenseDetail!L61 -> -12.995537 | M19: =-1*ExpenseDetail!M61 -> -12.995537 | N19: =-1*ExpenseDetail!N61 -> -12.995537 | O19: =-1*ExpenseDetail!O61 -> -12.995537 | P19: =-1*ExpenseDetail!P61 -> -13.879594 | Q19: =-1*ExpenseDetail!Q61 -> -13.879594 | ... AM19: =-1*ExpenseDetail!AM61 -> -13.963257
C20: Other business COGS cash | J20: =-1*ExpenseDetail!J62 -> -0.45875339 | K20: =-1*ExpenseDetail!K62 -> -0.45875339 | L20: =-1*ExpenseDetail!L62 -> -0.45875339 | M20: =-1*ExpenseDetail!M62 -> -0.45875339 | N20: =-1*ExpenseDetail!N62 -> -0.45875339 | O20: =-1*ExpenseDetail!O62 -> -0.45875339 | P20: =-1*ExpenseDetail!P62 -> -2.8642473 | Q20: =-1*ExpenseDetail!Q62 -> -2.8642473 | ... AM20: =-1*ExpenseDetail!AM62 -> -0.45875339
C21: Income taxes paid | J21: =-1*TaxEquity!J12 -> 0 | K21: =-1*TaxEquity!K12 -> 0 | L21: =-1*TaxEquity!L12 -> -430.68883 | M21: =-1*TaxEquity!M12 -> 0 | N21: =-1*TaxEquity!N12 -> 0 | O21: =-1*TaxEquity!O12 -> -209.16222 | P21: =-1*TaxEquity!P12 -> 0 | Q21: =-1*TaxEquity!Q12 -> 0 | ... AM21: =-1*TaxEquity!AM12 -> -214.70863
C22: Named other asset cash movement | J22: =-1*OtherBalances!J20 -> 0 | K22: =-1*OtherBalances!K20 -> 0 | L22: =-1*OtherBalances!L20 -> 0 | M22: =-1*OtherBalances!M20 -> 0 | N22: =-1*OtherBalances!N20 -> 0 | O22: =-1*OtherBalances!O20 -> 0 | P22: =-1*OtherBalances!P20 -> 0 | Q22: =-1*OtherBalances!Q20 -> 0 | ... AM22: =-1*OtherBalances!AM20 -> 0
C23: Named other liability cash movement | J23: =1*OtherBalances!J40 -> 0 | K23: =1*OtherBalances!K40 -> 0 | L23: =1*OtherBalances!L40 -> 0 | M23: =1*OtherBalances!M40 -> 0 | N23: =1*OtherBalances!N40 -> 0 | O23: =1*OtherBalances!O40 -> 0 | P23: =1*OtherBalances!P40 -> 0 | Q23: =1*OtherBalances!Q40 -> 0 | ... AM23: =1*OtherBalances!AM40 -> 0
C24: Direct CFO | I24: =H1Data!D104 -> 2235.8824 | J24: =SUM(J10:J23) -> 92.221836 | K24: =SUM(K10:K23) -> 388.30705 | L24: =SUM(L10:L23) -> 105.05724 | M24: =SUM(M10:M23) -> 162.20412 | N24: =SUM(N10:N23) -> 632.11671 | O24: =SUM(O10:O23) -> -56.326546 | P24: =SUM(P10:P23) -> 837.36313 | Q24: =SUM(Q10:Q23) -> 740.5397 | ... AM24: =SUM(AM10:AM23) -> -85.997571
C27: Cash capital expenditure | I27: =-H1Data!D111 -> -164.97009 | J27: =-1*Assets!J101 -> -43.762172 | K27: =-1*Assets!K101 -> -43.762172 | L27: =-1*Assets!L101 -> -43.762172 | M27: =-1*Assets!M101 -> -43.762172 | N27: =-1*Assets!N101 -> -43.762172 | O27: =-1*Assets!O101 -> -43.762172 | P27: =-1*Assets!P101 -> -45.950281 | Q27: =-1*Assets!Q101 -> -45.950281 | ... AM27: =-1*Assets!AM101 -> -48.247795
C28: PPE disposal proceeds | J28: =1*Assets!J102 -> 0 | K28: =1*Assets!K102 -> 0 | L28: =1*Assets!L102 -> 0 | M28: =1*Assets!M102 -> 0 | N28: =1*Assets!N102 -> 0 | O28: =1*Assets!O102 -> 0 | P28: =1*Assets!P102 -> 0 | Q28: =1*Assets!Q102 -> 0 | ... AM28: =1*Assets!AM102 -> 0
C29: Investment purchases | I29: =-H1Data!D110 -> -10452.63 | J29: =-1*Funding!J54 -> 0 | K29: =-1*Funding!K54 -> 0 | L29: =-1*Funding!L54 -> 0 | M29: =-1*Funding!M54 -> 0 | N29: =-1*Funding!N54 -> 0 | O29: =-1*Funding!O54 -> 0 | P29: =-1*Funding!P54 -> 0 | Q29: =-1*Funding!Q54 -> 0 | ... AM29: =-1*Funding!AM54 -> 0
C30: Investment redemptions | I30: =H1Data!D109 -> 11980.878 | J30: =1*Funding!J55 -> 0 | K30: =1*Funding!K55 -> 0 | L30: =1*Funding!L55 -> 0 | M30: =1*Funding!M55 -> 0 | N30: =1*Funding!N55 -> 0 | O30: =1*Funding!O55 -> 0 | P30: =1*Funding!P55 -> 0 | Q30: =1*Funding!Q55 -> 0 | ... AM30: =1*Funding!AM55 -> 0
C31: Cash investment income | I31: =H1Data!D93 -> 257.05764 | J31: =1*Funding!J59 -> 37.940387 | K31: =1*Funding!K59 -> 37.940387 | L31: =1*Funding!L59 -> 36.716504 | M31: =1*Funding!M59 -> 37.940387 | N31: =1*Funding!N59 -> 36.716504 | O31: =1*Funding!O59 -> 37.940387 | P31: =1*Funding!P59 -> 37.940387 | Q31: =1*Funding!Q59 -> 34.268737 | ... AM31: =1*Funding!AM59 -> 37.836725
C34: Net investing cash flow | I34: =H1Data!D105 -> 1612.0293 | J34: =SUM(J27:J31) -> -5.8217847 | K34: =SUM(K27:K31) -> -5.8217847 | L34: =SUM(L27:L31) -> -7.0456682 | M34: =SUM(M27:M31) -> -5.8217847 | N34: =SUM(N27:N31) -> -7.0456682 | O34: =SUM(O27:O31) -> -5.8217847 | P34: =SUM(P27:P31) -> -8.0098933 | Q34: =SUM(Q27:Q31) -> -11.681544 | ... AM34: =SUM(AM27:AM31) -> -10.41107
C37: Effective loan draw | I37: =H1Data!D112 -> 1975.8432 | J37: =1*Funding!J65 -> 0 | K37: =1*Funding!K65 -> 0 | L37: =1*Funding!L65 -> 0 | M37: =1*Funding!M65 -> 0 | N37: =1*Funding!N65 -> 0 | O37: =1*Funding!O65 -> 0 | P37: =1*Funding!P65 -> 0 | Q37: =1*Funding!Q65 -> 0 | ... AM37: =1*Funding!AM65 -> 0
C38: Effective loan principal repayment | I38: =-H1Data!D113 -> -1829.95 | J38: =-1*Funding!J66 -> 0 | K38: =-1*Funding!K66 -> 0 | L38: =-1*Funding!L66 -> 0 | M38: =-1*Funding!M66 -> 0 | N38: =-1*Funding!N66 -> 0 | O38: =-1*Funding!O66 -> 0 | P38: =-1*Funding!P66 -> 0 | Q38: =-1*Funding!Q66 -> 0 | ... AM38: =-1*Funding!AM66 -> 0
C39: Effective lease principal repayment | J39: =-1*Funding!J47 -> -1.1167446 | K39: =-1*Funding!K47 -> -1.1167446 | L39: =-1*Funding!L47 -> -1.1167446 | M39: =-1*Funding!M47 -> -1.1167446 | N39: =-1*Funding!N47 -> -1.1167446 | O39: =-1*Funding!O47 -> -1.1167446 | P39: =-1*Funding!P47 -> -1.1167446 | Q39: =-1*Funding!Q47 -> -1.1167446 | ... AM39: =-1*Funding!AM47 -> 0
C40: Loan and lease interest cash paid | J40: =-1*Monthly_PL!J28 -> -4.1053422 | K40: =-1*Monthly_PL!K28 -> -4.1010741 | L40: =-1*Monthly_PL!L28 -> -3.964651 | M40: =-1*Monthly_PL!M28 -> -4.0925379 | N40: =-1*Monthly_PL!N28 -> -3.9563902 | O40: =-1*Monthly_PL!O28 -> -4.0840017 | P40: =-1*Monthly_PL!P28 -> -4.0797336 | Q40: =-1*Monthly_PL!Q28 -> -3.6810656 | ... AM40: =-1*Monthly_PL!AM28 -> -2.4153845
C41: Gross new equity proceeds | J41: =1*TaxEquity!J40 -> 0 | K41: =1*TaxEquity!K40 -> 0 | L41: =1*TaxEquity!L40 -> 0 | M41: =1*TaxEquity!M40 -> 0 | N41: =1*TaxEquity!N40 -> 0 | O41: =1*TaxEquity!O40 -> 0 | P41: =1*TaxEquity!P40 -> 0 | Q41: =1*TaxEquity!Q40 -> 0 | ... AM41: =1*TaxEquity!AM40 -> 0
C42: Equity issuance fee | J42: =-1*TaxEquity!J41 -> 0 | K42: =-1*TaxEquity!K41 -> 0 | L42: =-1*TaxEquity!L41 -> 0 | M42: =-1*TaxEquity!M41 -> 0 | N42: =-1*TaxEquity!N41 -> 0 | O42: =-1*TaxEquity!O41 -> 0 | P42: =-1*TaxEquity!P41 -> 0 | Q42: =-1*TaxEquity!Q41 -> 0 | ... AM42: =-1*TaxEquity!AM41 -> 0
C43: Parent and NCI cash dividends | J43: =-1*Funding!J72 -> 0 | K43: =-1*Funding!K72 -> 0 | L43: =-1*Funding!L72 -> 0 | M43: =-1*Funding!M72 -> 0 | N43: =-1*Funding!N72 -> 0 | O43: =-1*Funding!O72 -> 0 | P43: =-1*Funding!P72 -> 0 | Q43: =-1*Funding!Q72 -> 0 | ... AM43: =-1*Funding!AM72 -> 0
C44: Share repurchase cash | J44: =-TaxEquity!J53 -> 0 | K44: =-TaxEquity!K53 -> 0 | L44: =-TaxEquity!L53 -> 0 | M44: =-TaxEquity!M53 -> 0 | N44: =-TaxEquity!N53 -> 0 | O44: =-TaxEquity!O53 -> 0 | P44: =-TaxEquity!P53 -> 0 | Q44: =-TaxEquity!Q53 -> 0 | ... AM44: =-TaxEquity!AM53 -> 0
C45: Net financing cash flow | I45: =H1Data!D106 -> -3503.3588 | J45: =SUM(J37:J44) -> -5.2220868 | K45: =SUM(K37:K44) -> -5.2178187 | L45: =SUM(L37:L44) -> -5.0813956 | M45: =SUM(M37:M44) -> -5.2092825 | N45: =SUM(N37:N44) -> -5.0731347 | O45: =SUM(O37:O44) -> -5.2007463 | P45: =SUM(P37:P44) -> -5.1964782 | Q45: =SUM(Q37:Q44) -> -4.7978102 | ... AM45: =SUM(AM37:AM44) -> -2.4153845
C47: Cash FX | I47: =H1Data!D107 -> -7.0988049 | J47: =Inputs!J61 -> 0 | K47: =Inputs!K61 -> 0 | L47: =Inputs!L61 -> 0 | M47: =Inputs!M61 -> 0 | N47: =Inputs!N61 -> 0 | O47: =Inputs!O61 -> 0 | P47: =Inputs!P61 -> 0 | Q47: =Inputs!Q61 -> 0 | ... AM47: =Inputs!AM61 -> 0
C48: Net change in cash | I48: =SUM(I24,I34,I45,I47) -> 337.4541 | J48: =J24+J34+J45+J47 -> 81.177965 | K48: =K24+K34+K45+K47 -> 377.26745 | L48: =L24+L34+L45+L47 -> 92.93018 | M48: =M24+M34+M45+M47 -> 151.17306 | N48: =N24+N34+N45+N47 -> 619.9979 | O48: =O24+O34+O45+O47 -> -67.349077 | P48: =P24+P34+P45+P47 -> 824.15676 | Q48: =Q24+Q34+Q45+Q47 -> 724.06035 | ... AM48: =AM24+AM34+AM45+AM47 -> -98.824025
C50: Opening cash equivalents | I50: =H1Data!D108 -> 721.04459 | J50: =H1Data!D9 -> 1058.4987 | K50: =Monthly_CF!J51 -> 1139.6766 | L50: =Monthly_CF!K51 -> 1516.9441 | M50: =Monthly_CF!L51 -> 1609.8743 | N50: =Monthly_CF!M51 -> 1761.0473 | O50: =Monthly_CF!N51 -> 2381.0452 | P50: =Monthly_CF!O51 -> 2313.6962 | Q50: =Monthly_CF!P51 -> 3137.8529 | R50: =Monthly_CF!Q51 -> 3861.9133 | ... AM50: =Monthly_CF!AL51 -> 2632.302
C51: Closing cash equivalents | I51: =H1Data!D9 -> 1058.4987 | J51: =J50+J48 -> 1139.6766 | K51: =K50+K48 -> 1516.9441 | L51: =L50+L48 -> 1609.8743 | M51: =M50+M48 -> 1761.0473 | N51: =N50+N48 -> 2381.0452 | O51: =O50+O48 -> 2313.6962 | P51: =P50+P48 -> 3137.8529 | Q51: =Q50+Q48 -> 3861.9133 | ... AM51: =AM50+AM48 -> 2533.478
C53: Indirect CFO: consolidated NI | J53: =Monthly_PL!J31 -> 207.04207 | K53: =Monthly_PL!K31 -> 277.81829 | L53: =Monthly_PL!L31 -> 308.1352 | M53: =Monthly_PL!M31 -> 322.47864 | N53: =Monthly_PL!N31 -> 327.10814 | O53: =Monthly_PL!O31 -> 332.09933 | P53: =Monthly_PL!P31 -> 352.35438 | Q53: =Monthly_PL!Q31 -> 348.6448 | ... AM53: =Monthly_PL!AM31 -> 336.97149
C54: Add total D&A | J54: =Assets!J100 -> 26.380476 | K54: =Assets!K100 -> 26.591641 | L54: =Assets!L100 -> 26.802806 | M54: =Assets!M100 -> 27.013971 | N54: =Assets!N100 -> 27.225136 | O54: =Assets!O100 -> 27.436302 | P54: =Assets!P100 -> 27.647467 | Q54: =Assets!Q100 -> 27.86919 | ... AM54: =Assets!AM100 -> 31.609107
...

Sheet Revenue
C2: 公牛集团 Revenue
C3: RMB million except stated units. H1 2026 actual aggregate is separate; monthly forecast begins July 2026.
D6: Not disclosed | E6: Not disclosed | F6: Not disclosed | G6: Not disclosed | H6: Not disclosed | I6: H1: see H1Actual | J6: Forecast | K6: Forecast | L6: Forecast | M6: Forecast | N6: Forecast | O6: Forecast | P6: Forecast | Q6: Forecast | R6: Forecast | S6: Forecast | T6: Forecast | U6: Forecast | V6: Forecast | W6: Forecast | X6: Forecast | Y6: Forecast | Z6: Forecast | AA6: Forecast | AB6: Forecast | AC6: Forecast | AD6: Forecast | AE6: Forecast | AF6: Forecast | AG6: Forecast | AH6: Forecast | AI6: Forecast | AJ6: Forecast | AK6: Forecast | AL6: Forecast | AM6: Forecast
D7: 46053 | E7: 46081 | F7: 46112 | G7: 46142 | H7: 46173 | I7: 46203 | J7: 46234 | K7: 46265 | L7: 46295 | M7: 46326 | N7: 46356 | O7: 46387 | P7: 46418 | Q7: 46446 | R7: 46477 | S7: 46507 | T7: 46538 | U7: 46568 | V7: 46599 | W7: 46630 | X7: 46660 | Y7: 46691 | Z7: 46721 | AA7: 46752 | AB7: 46783 | AC7: 46812 | AD7: 46843 | AE7: 46873 | AF7: 46904 | AG7: 46934 | AH7: 46965 | AI7: 46996 | AJ7: 47026 | AK7: 47057 | AL7: 47087 | AM7: 47118
C9: 电连接产品
C10: Sales units | J10: =(SourceAnalysis!D9-(SourceHistory!F64-SourceHistory!F66)*SourceAnalysis!D9/SourceAnalysis!D24)*1000000/SourceAnalysis!D13/6*(1+Inputs!J9)*Inputs!J5 -> 48342423 | K10: =(SourceAnalysis!D9-(SourceHistory!F64-SourceHistory!F66)*SourceAnalysis!D9/SourceAnalysis!D24)*1000000/SourceAnalysis!D13/6*(1+Inputs!K9)*Inputs!K5 -> 48342423 | L10: =(SourceAnalysis!D9-(SourceHistory!F64-SourceHistory!F66)*SourceAnalysis!D9/SourceAnalysis!D24)*1000000/SourceAnalysis!D13/6*(1+Inputs!L9)*Inputs!L5 -> 48342423 | M10: =(SourceAnalysis!D9-(SourceHistory!F64-SourceHistory!F66)*SourceAnalysis!D9/SourceAnalysis!D24)*1000000/SourceAnalysis!D13/6*(1+Inputs!M9)*Inputs!M5 -> 48342423 | N10: =(SourceAnalysis!D9-(SourceHistory!F64-SourceHistory!F66)*SourceAnalysis!D9/SourceAnalysis!D24)*1000000/SourceAnalysis!D13/6*(1+Inputs!N9)*Inputs!N5 -> 48342423 | O10: =(SourceAnalysis!D9-(SourceHistory!F64-SourceHistory!F66)*SourceAnalysis!D9/SourceAnalysis!D24)*1000000/SourceAnalysis!D13/6*(1+Inputs!O9)*Inputs!O5 -> 48342423 | P10: =((SourceHistory!F65-SourceHistory!F67)*SourceAnalysis!D9/SourceAnalysis!D24*1000000/SourceAnalysis!D13/6)*(1+Inputs!P9)*Inputs!P5 -> 51490346 | Q10: =((SourceHistory!F65-SourceHistory!F67)*SourceAnalysis!D9/SourceAnalysis!D24*1000000/SourceAnalysis!D13/6)*(1+Inputs!Q9)*Inputs!Q5 -> 51490346 | R10: =((SourceHistory!F65-SourceHistory!F67)*SourceAnalysis!D9/SourceAnalysis!D24*1000000/SourceAnalysis!D13/6)*(1+Inputs!R9)*Inputs!R5 -> 51490346 | S10: =((SourceHistory!F65-SourceHistory!F67)*SourceAnalysis!D9/SourceAnalysis!D24*1000000/SourceAnalysis!D13/6)*(1+Inputs!S9)*Inputs!S5 -> 51490346 | T10: =((SourceHistory!F65-SourceHistory!F67)*SourceAnalysis!D9/SourceAnalysis!D24*1000000/SourceAnalysis!D13/6)*(1+Inputs!T9)*Inputs!T5 -> 51490346 | U10: =((SourceHistory!F65-SourceHistory!F67)*SourceAnalysis!D9/SourceAnalysis!D24*1000000/SourceAnalysis!D13/6)*(1+Inputs!U9)*Inputs!U5 -> 51490346 | V10: =Revenue!J10*(1+Inputs!V9)*Inputs!V5 -> 49309272 | W10: =Revenue!K10*(1+Inputs!W9)*Inputs!W5 -> 49309272 | X10: =Revenue!L10*(1+Inputs!X9)*Inputs!X5 -> 49309272 | Y10: =Revenue!M10*(1+Inputs!Y9)*Inputs!Y5 -> 49309272 | Z10: =Revenue!N10*(1+Inputs!Z9)*Inputs!Z5 -> 49309272 | AA10: =Revenue!O10*(1+Inputs!AA9)*Inputs!AA5 -> 49309272 | AB10: =Revenue!P10*(1+Inputs!AB9)*Inputs!AB5 -> 52520153 | AC10: =Revenue!Q10*(1+Inputs!AC9)*Inputs!AC5 -> 52520153 | ... AM10: =Revenue!AA10*(1+Inputs!AM9)*Inputs!AM5 -> 50295457
C11: Net ASP incl mix RMB | J11: =SourceAnalysis!D13*(1+Inputs!J10) -> 12.218193 | K11: =SourceAnalysis!D13*(1+Inputs!K10) -> 12.218193 | L11: =SourceAnalysis!D13*(1+Inputs!L10) -> 12.218193 | M11: =SourceAnalysis!D13*(1+Inputs!M10) -> 12.218193 | N11: =SourceAnalysis!D13*(1+Inputs!N10) -> 12.218193 | O11: =SourceAnalysis!D13*(1+Inputs!O10) -> 12.218193 | P11: =(SourceAnalysis!D13)*(1+Inputs!P10) -> 12.218193 | Q11: =(SourceAnalysis!D13)*(1+Inputs!Q10) -> 12.218193 | R11: =(SourceAnalysis!D13)*(1+Inputs!R10) -> 12.218193 | S11: =(SourceAnalysis!D13)*(1+Inputs!S10) -> 12.218193 | T11: =(SourceAnalysis!D13)*(1+Inputs!T10) -> 12.218193 | U11: =(SourceAnalysis!D13)*(1+Inputs!U10) -> 12.218193 | V11: =Revenue!J11*(1+Inputs!V10) -> 12.218193 | W11: =Revenue!K11*(1+Inputs!W10) -> 12.218193 | X11: =Revenue!L11*(1+Inputs!X10) -> 12.218193 | Y11: =Revenue!M11*(1+Inputs!Y10) -> 12.218193 | Z11: =Revenue!N11*(1+Inputs!Z10) -> 12.218193 | AA11: =Revenue!O11*(1+Inputs!AA10) -> 12.218193 | AB11: =Revenue!P11*(1+Inputs!AB10) -> 12.218193 | AC11: =Revenue!Q11*(1+Inputs!AC10) -> 12.218193 | ... AM11: =Revenue!AA11*(1+Inputs!AM10) -> 12.218193
C12: Product revenue | J12: =J10*J11/1000000 -> 590.65705 | K12: =K10*K11/1000000 -> 590.65705 | L12: =L10*L11/1000000 -> 590.65705 | M12: =M10*M11/1000000 -> 590.65705 | N12: =N10*N11/1000000 -> 590.65705 | O12: =O10*O11/1000000 -> 590.65705 | P12: =P10*P11/1000000 -> 629.11898 | Q12: =Q10*Q11/1000000 -> 629.11898 | ... AM12: =AM10*AM11/1000000 -> 614.5196
C13: Revenue unit/ASP check | J13: =J10*J11/1000000-J12 -> 0 | K13: =K10*K11/1000000-K12 -> 0 | L13: =L10*L11/1000000-L12 -> 0 | M13: =M10*M11/1000000-M12 -> 0 | N13: =N10*N11/1000000-N12 -> 0 | O13: =O10*O11/1000000-O12 -> 0 | P13: =P10*P11/1000000-P12 -> 0 | Q13: =Q10*Q11/1000000-Q12 -> 0 | ... AM13: =AM10*AM11/1000000-AM12 -> 0
C18: 智能电工照明
